<?xml version="1.0" ?>
<!-- =================================================================================== -->
<!-- |    This document was autogenerated by xacro from src/aurora_arm/description/robot_ign_v2.xacro | -->
<!-- |    EDITING THIS FILE BY HAND IS NOT RECOMMENDED                                 | -->
<!-- =================================================================================== -->
<robot name="aurora_arm" xmlns:xacro="http://www.ros.org/wiki/xacro"> 
  <material name="grey">
    <color rgba="0.5 0.5 0.5 1.0"/>
  </material>
  <material name="red">
    <color rgba="1.0 0.0 0.0 1.0"/>
  </material>
  <material name="black">
    <color rgba="0.0 0.0 0.0 1.0"/>
  </material>
  <link name="base_link">
    <!-- 慣性プロパティを追加してベースを安定させる -->
    <inertial>
      <origin rpy="0 0 0" xyz="0 0 0"/>
      <mass value="100.0"/>
      <!-- 重い質量でベースを安定化 -->
      <inertia ixx="10.0" ixy="0.0" ixz="0.0" iyy="10.0" iyz="0.0" izz="10.0"/>
    </inertial>
    <collision>
      <geometry>
        <box size="0.2 0.2 0.1"/>
        <!-- 衝突判定用のボックス -->
      </geometry>
      <origin rpy="0 0 0" xyz="0 0 0.05"/>
    </collision>
  </link>
  <!-- ベースを完全に固定 -->
  <gazebo reference="base_link">
    <static>true</static>
    <material>Gazebo/Gray</material>
  </gazebo>
  <joint name="base" type="fixed">
    <parent link="base_link"/>
    <child link="state_link"/>
    <origin rpy="1.5707963267948966 0 0" xyz="0 0 0"/>
  </joint>
  <link name="state_link">
    <visual>
      <geometry>
        <mesh filename="package://aurora_arm/meshes/base_link.stl" scale="0.001 0.001 0.001"/>
      </geometry>
      <origin rpy="0 0 0" xyz="0 0 0"/>
      <material name="grey"/>
    </visual>
    <inertial>
      <origin rpy="0 0 0" xyz="-1.2836056698212661e-14 0.010046058033552938 1.777847188118097e-17"/>
      <mass value="50"/>
      <inertia ixx="0.060326" ixy="-0.0" ixz="-0.0" iyy="0.079337" iyz="0.0" izz="0.019557"/>
    </inertial>
    <collision>
      <origin rpy="0 0 0" xyz="0 0 0"/>
      <geometry>
        <mesh filename="package://aurora_arm/meshes/base_link.stl" scale="0.001 0.001 0.001"/>
      </geometry>
    </collision>
  </link>
  <gazebo reference="state_link">
    <material>Gazebo/Gray</material>
  </gazebo>
  <joint name="rotation1" type="revolute">
    <parent link="state_link"/>
    <child link="arm_link_1"/>
    <origin rpy="0 0 0" xyz="0.0 0.03 0.0"/>
    <axis xyz="0.0 1.0 0.0"/>
    <limit effort="100" lower="-2.748894" upper="-0.392699" velocity="100"/>
    <dynamics damping="10.0" friction="1.0"/>
    <!-- ダンピングとフリクション追加 -->
  </joint>
  <link name="arm_link_1">
    <visual>
      <geometry>
        <mesh filename="package://aurora_arm/meshes/arm1_link_1.stl" scale="0.001 0.001 0.001"/>
      </geometry>
      <origin rpy="0 0 0" xyz="-0.0 -0.03 -0.0"/>
      <material name="grey"/>
    </visual>
    <inertial>
      <origin rpy="0 0 0" xyz="1.2424219094974304e-14 -0.001611517508914171 2.4814919210499358e-14"/>
      <mass value="1.039221830408455"/>
      <inertia ixx="0.00099" ixy="-0.0" ixz="-0.0" iyy="0.001733" iyz="0.0" izz="0.000903"/>
    </inertial>
    <collision>
      <origin rpy="0 0 0" xyz="-0.0 -0.03 -0.0"/>
      <geometry>
        <mesh filename="package://aurora_arm/meshes/arm1_link_1.stl" scale="0.001 0.001 0.001"/>
      </geometry>
    </collision>
  </link>
  <gazebo reference="arm_link_1">
    <material>Gazebo/Gray</material>
  </gazebo>
  <joint name="rotation2" type="revolute">
    <parent link="arm_link_1"/>
    <child link="arm_link_2"/>
    <origin rpy="0 0 0" xyz="-5e-06 0.015 -0.02"/>
    <axis xyz="-0.00026 -0.0 -1.0"/>
    <limit effort="100" lower="-0.785398" upper="1.570796" velocity="100"/>
    <dynamics damping="10.0" friction="1.0"/>
    <!-- ダンピングとフリクション追加 -->
  </joint>
  <link name="arm_link_2">
    <visual>
      <geometry>
        <mesh filename="package://aurora_arm/meshes/arm2_link_1.stl" scale="0.001 0.001 0.001"/>
      </geometry>
      <origin rpy="0 0 0" xyz="5e-06 -0.045 0.02"/>
      <material name="grey"/>
    </visual>
    <inertial>
      <origin rpy="0 0 0" xyz="-0.08436856236861598 0.08574082978509752 0.02002195399237318"/>
      <mass value="1.556523004661359"/>
      <inertia ixx="0.004388" ixy="0.004054" ixz="1e-06" iyy="0.004258" iyz="-1e-06" izz="0.008213"/>
    </inertial>
    <collision>
      <origin rpy="0 0 0" xyz="5e-06 -0.045 0.02"/>
      <geometry>
        <mesh filename="package://aurora_arm/meshes/arm2_link_1.stl" scale="0.001 0.001 0.001"/>
      </geometry>
    </collision>
  </link>
  <gazebo reference="arm_link_2">
    <material>Gazebo/Gray</material>
  </gazebo>
  <joint name="rotation3" type="revolute">
    <parent link="arm_link_2"/>
    <child link="arm_link_3"/>
    <origin rpy="0 0 0" xyz="-0.175343 0.178192 0.030046"/>
    <axis xyz="-0.00026 0.0 -1.0"/>
    <limit effort="100" lower="-3.141593" upper="0.785398" velocity="100"/>
    <dynamics damping="10.0" friction="1.0"/>
    <!-- ダンピングとフリクション追加 -->
  </joint>
  <link name="arm_link_3">
    <visual>
      <geometry>
        <mesh filename="package://aurora_arm/meshes/arm3_link_1.stl" scale="0.001 0.001 0.001"/>
      </geometry>
      <origin rpy="0 0 0" xyz="0.175348 -0.223192 -0.010046"/>
      <material name="grey"/>
    </visual>
    <inertial>
      <origin rpy="0 0 0" xyz="0.09386781150408618 0.08296159224208283 -0.010024798863264761"/>
      <mass value="1.4275537558266949"/>
      <inertia ixx="0.003111" ixy="-0.003281" ixz="1e-06" iyy="0.003931" iyz="1e-06" izz="0.006708"/>
    </inertial>
    <collision>
      <origin rpy="0 0 0" xyz="0.175348 -0.223192 -0.010046"/>
      <geometry>
        <mesh filename="package://aurora_arm/meshes/arm3_link_1.stl" scale="0.001 0.001 0.001"/>
      </geometry>
    </collision>
  </link>
  <gazebo reference="arm_link_3">
    <material>Gazebo/Gray</material>
  </gazebo>
  <joint name="rotation4" type="revolute">
    <parent link="arm_link_3"/>
    <child link="arm_link_4"/>
    <origin rpy="0 0 0" xyz="0.187345 0.16553 -0.020049"/>
    <axis xyz="-0.00026 0.0 -1.0"/>
    <limit effort="100" lower="-0.872665" upper="1.570796" velocity="100"/>
    <dynamics damping="10.0" friction="1.0"/>
    <!-- ダンピングとフリクション追加 -->
  </joint>
  <link name="arm_link_4">
    <visual>
      <geometry>
        <mesh filename="package://aurora_arm/meshes/arm4_link_1.stl" scale="0.001 0.001 0.001"/>
      </geometry>
      <origin rpy="0 0 0" xyz="-0.011997 -0.388722 0.010003"/>
      <material name="grey"/>
    </visual>
    <inertial>
      <origin rpy="0 0 0" xyz="0.04283652196076893 0.03784496310007385 0.00998873232310213"/>
      <mass value="0.5345901994447376"/>
      <inertia ixx="0.000635" ixy="-0.000405" ixz="0.0" iyy="0.000736" iyz="0.0" izz="0.00085"/>
    </inertial>
    <collision>
      <origin rpy="0 0 0" xyz="-0.011997 -0.388722 0.010003"/>
      <geometry>
        <mesh filename="package://aurora_arm/meshes/arm4_link_1.stl" scale="0.001 0.001 0.001"/>
      </geometry>
    </collision>
  </link>
  <gazebo reference="arm_link_4">
    <material>Gazebo/Gray</material>
  </gazebo>
  <joint name="rotation5" type="revolute">
    <parent link="arm_link_4"/>
    <child link="arm_link_5"/>
    <origin rpy="0 0 0" xyz="0.01417 0.114124 0.009996"/>
    <axis xyz="0.749398 0.662119 -0.000195"/>
    <limit effort="100" lower="-2.356194" upper="2.356194" velocity="100"/>
  </joint>
  <link name="arm_link_5">
    <visual>
      <geometry>
        <mesh filename="package://aurora_arm/meshes/arm5_link_1.stl" scale="0.001 0.001 0.001"/>
      </geometry>
      <origin rpy="0 0 0" xyz="-0.026167 -0.502846 7e-06"/>
      <material name="grey"/>
    </visual>
    <inertial>
      <origin rpy="0 0 0" xyz="0.07201323471428178 -0.0379807321383373 -1.8546487173911982e-05"/>
      <mass value="0.15083462441733284"/>
      <inertia ixx="0.000134" ixy="2e-06" ixz="-0.0" iyy="0.000134" iyz="0.0" izz="6e-06"/>
    </inertial>
    <collision>
      <origin rpy="0 0 0" xyz="-0.026167 -0.502846 7e-06"/>
      <geometry>
        <mesh filename="package://aurora_arm/meshes/arm5_link_1.stl" scale="0.001 0.001 0.001"/>
      </geometry>
    </collision>
  </link>
  <gazebo reference="arm_link_5">
    <material>Gazebo/Gray</material>
  </gazebo>
  <joint name="slide1" type="prismatic">
    <parent link="arm_link_5"/>
    <child link="hand_link_1"/>
    <origin rpy="0 0 0" xyz="0.072052 -0.03801 0.049981"/>
    <axis xyz="-0.00052 0.000294 -1.0"/>
    <limit effort="100" lower="0.001" upper="0.04" velocity="100"/>
    <dynamics damping="5.0" friction="0.5"/>
    <!-- ダンピングとフリクション追加 -->
  </joint>
  <link name="hand_link_1">
    <visual>
      <geometry>
        <mesh filename="package://aurora_arm/meshes/hand1_link_1.stl" scale="0.001 0.001 0.001"/>
      </geometry>
      <origin rpy="0 0 0" xyz="-0.098219 -0.464836 -0.049974"/>
      <material name="grey"/>
    </visual>
    <inertial>
      <origin rpy="0 0 0" xyz="0.02626289486026448 0.023237763910856968 -0.010145280708131962"/>
      <mass value="0.0941999999999979"/>
      <inertia ixx="1.5e-05" ixy="-1.3e-05" ixz="0.0" iyy="1.8e-05" iyz="0.0" izz="3.2e-05"/>
    </inertial>
    <collision>
      <origin rpy="0 0 0" xyz="-0.098219 -0.464836 -0.049974"/>
      <geometry>
        <mesh filename="package://aurora_arm/meshes/hand1_link_1.stl" scale="0.001 0.001 0.001"/>
      </geometry>
    </collision>
  </link>
  <gazebo reference="hand_link_1">
    <material>Gazebo/Gray</material>
  </gazebo>
  <joint name="slide2" type="prismatic">
    <parent link="arm_link_5"/>
    <child link="hand_link_2"/>
    <origin rpy="0 0 0" xyz="0.071974 -0.037951 -0.050019"/>
    <axis xyz="0.00052 -0.000294 1.0"/>
    <limit effort="100" lower="0.001" upper="0.04" velocity="100"/>
    <dynamics damping="5.0" friction="0.5"/>
    <!-- ダンピングとフリクション追加 -->
  </joint>
  <link name="hand_link_2">
    <visual>
      <geometry>
        <mesh filename="package://aurora_arm/meshes/hand2_link_1.stl" scale="0.001 0.001 0.001"/>
      </geometry>
      <origin rpy="0 0 0" xyz="-0.098141 -0.464895 0.050026"/>
      <material name="grey"/>
    </visual>
    <inertial>
      <origin rpy="0 0 0" xyz="0.02629947971429203 0.023202160214768452 0.010132511217204668"/>
      <mass value="0.09419999999999831"/>
      <inertia ixx="1.5e-05" ixy="-1.3e-05" ixz="-0.0" iyy="1.8e-05" iyz="-0.0" izz="3.2e-05"/>
    </inertial>
    <collision>
      <origin rpy="0 0 0" xyz="-0.098141 -0.464895 0.050026"/>
      <geometry>
        <mesh filename="package://aurora_arm/meshes/hand2_link_1.stl" scale="0.001 0.001 0.001"/>
      </geometry>
    </collision>
  </link>
  <gazebo reference="hand_link_2">
    <material>Gazebo/Gray</material>
  </gazebo>
</robot>
